<robot xmlns:xacro="http://www.ros.org/wiki/xacro" name="ezrassor">
    <xacro:macro name="drum" params="pos">
        <link name="drum_${pos}">
            <collision name="collision">
                <origin xyz="0 0 0" rpy="0 1.5707 1.5707"/>
                <geometry>
                    <cylinder radius="0.1839" length="1.0"/>
                </geometry>
            </collision>
            <visual name="drum_front_visual">
                <xacro:if value='${pos == "front"}'>
                    <origin xyz="0 0 0" rpy="0 0 0"/>
                </xacro:if>
                <xacro:unless value='${pos == "front"}'>
                    <origin xyz="0 0 0" rpy="3.1415 0 3.14159"/>
                </xacro:unless>
                <geometry>
                    <xacro:robot_arm_drum />
                </geometry>
            </visual>
            <inertial>
                <xacro:if value='${pos == "front"}'>
                    <origin xyz="0 0 0" rpy="0 0 0"/>
                </xacro:if>
                <xacro:unless value='${pos == "front"}'>
                    <origin xyz="0 0 0" rpy="0 0 3.14159"/>
                </xacro:unless>
                <mass value="2"/>
                <xacro:cylinder_inertia m="2" r="0.1839" h="1.0"/>
            </inertial>
        </link>

        <joint type="continuous" name="drum_${pos}_joint">
            <xacro:if value='${pos == "front"}'>
                <origin xyz="0.388245 0 0" rpy="3.1415 0 0"/>
            </xacro:if>
            <xacro:unless value='${pos == "front"}'>
                <origin xyz="-0.388245 0 0" rpy="3.1415 0 0"/>
            </xacro:unless>
            <child link="drum_${pos}"/>
            <parent link="arm_${pos}"/>
            <axis xyz="0 1 0" rpy="0 0 0"/>
            <limit effort="100" velocity="100"/>
            <joint_properties damping="0.0" friction="0.0"/>
        </joint>

    </xacro:macro>
</robot>