<robot xmlns:xacro="http://www.ros.org/wiki/xacro" name="ezrassor">
    
    <xacro:macro name="paver_arm" params="model">
        <link name="link1">
            <inertial>
                <origin xyz="0.0 0.0 0.0" rpy="0.0 0.0 0.0"/>
                <mass value="0.5"/>
                <inertia ixx="0.0" ixy="0.0" ixz="0.0" iyy="0.0" iyz="0.0" izz="0.0"/>
            </inertial>
            <visual name="">
                <origin xyz="0.0 0.0 0.0" rpy="0.0 0.0 0.0"/>
                <geometry>
                    <xacro:link1/>
                </geometry>
            </visual>
            <collision>
                <origin xyz="0.0 0.0 0.0" rpy="0.0 0.0 0.0"/>
                <geometry>
                    <xacro:link1/>
                </geometry>
            </collision>
        </link>

        <link name="link2">
            <inertial>
                <origin xyz="0.0 0.0 0.0" rpy="0.0 0.0 0.0"/>
                <mass value="0.5"/>
                <inertia ixx="0.0" ixy="0.0" ixz="0.0" iyy="0.0" iyz="0.0" izz="0.0"/>
            </inertial>
            <visual name="">
                <origin xyz="0.0 0.08 0.135" rpy="0.0 0.0 0.0"/>
                <geometry>
                    <xacro:link2/>
                </geometry>
            </visual>
            <collision>
                <origin xyz="0.0 0.08 0.135" rpy="0.0 0.0 0.0"/>
                <geometry>
                    <xacro:link2/>
                </geometry>
            </collision>
        </link>

        <link name="link3">
            <inertial>
                <origin xyz="0.0 0.0 0.0" rpy="0.0 0.0 0.0"/>
                <mass value="0.5"/>
                <inertia ixx="0.0" ixy="0.0" ixz="0.0" iyy="0.0" iyz="0.0" izz="0.0"/>
            </inertial>
            <visual name="">
                <origin xyz="0.25 0.1 0.0" rpy="0.0 0.0 0.0"/>
                <geometry>
                    <xacro:link3/>
                </geometry>
            </visual>
            <collision>
                <origin xyz="0.25 0.1 0.0" rpy="0.0 0.0 0.0"/>
                <geometry>
                    <xacro:link3/>
                </geometry>
            </collision>
        </link> 

        <link name="link4">
            <inertial>
                <origin xyz="0.0 0.0 0.0" rpy="0.0 0.0 0.0"/>
                <mass value="0.5"/>
                <inertia ixx="0.0" ixy="0.0" ixz="0.0" iyy="0.0" iyz="0.0" izz="0.0"/>
            </inertial>
            <visual name="">
                <origin xyz="0.23 0.0 0.0" rpy="0.0 0.0 0.0"/>
                <geometry>
                    <xacro:link4/>
                </geometry>
            </visual>
            <collision>
                <origin xyz="0.23 0.0 0.0" rpy="0.0 0.0 0.0"/>
                <geometry>
                    <xacro:link4/>
                </geometry>
            </collision>
        </link>

        <link name="link5">
            <inertial>
                <origin xyz="0.0 0.0 0.0" rpy="0.0 0.0 0.0"/>
                <mass value="0.5"/>
                <inertia ixx="0.0" ixy="0.0" ixz="0.0" iyy="0.0" iyz="0.0" izz="0.0"/>
            </inertial>
            <visual name="">
                <origin xyz="0.0 0.12 0.0" rpy="0.0 0.0 0.0"/>
                <geometry>
                    <xacro:link5/>
                </geometry>
            </visual>
            <collision>
                <origin xyz="0.0 0.12 0.0" rpy="0.0 0.0 0.0"/>
                <geometry>
                    <xacro:link5/>
                </geometry>
            </collision>
        </link>

        <link name="link6">
            <inertial>
                <origin xyz="0.0 0.0 0.0" rpy="0.0 0.0 0.0"/>
                <mass value="0.5"/>
                <inertia ixx="0.0" ixy="0.0" ixz="0.0" iyy="0.0" iyz="0.0" izz="0.0"/>
            </inertial>
            <visual name="">
                <origin xyz="0.096 0 -0.24" rpy="0.0 0.0 0.0"/>
                <geometry>
                    <xacro:link6/>
                </geometry>
            </visual>
            <collision>
                <origin xyz="0.096 0 -0.24" rpy="0.0 0.0 0.0"/>
                <geometry>
                    <xacro:link6/>
                </geometry>
            </collision>
        </link>

        <link name="grabber1">
            <inertial>
                <origin xyz="0.0 0.0 0.0" rpy="0.0 0.0 0.0"/>
                <mass value="0.1"/>
                <inertia ixx="0.0" ixy="0.0" ixz="0.0" iyy="0.0" iyz="0.0" izz="0.0"/>
            </inertial>
            <visual name="">
                <origin xyz="0.0 0.0 0.0" rpy="0.0 0.0 0.0"/>
                <geometry>
                    <xacro:grabber1/>
                </geometry>
                <material name="">
                    <color rgba="1.0 0.0 0.0 1.0"/>
                    <texture filename=""/>
                </material>
            </visual>
            <collision>
                <origin xyz="0.0 0.0 0.0" rpy="0.0 0.0 0.0"/>
                <geometry>
                    <xacro:grabber1/>
                </geometry>
            </collision>
        </link>

        <link name="grabber2">
            <inertial>
                <origin xyz="0.0 0.0 0.0" rpy="0.0 0.0 0.0"/>
                <mass value="0.1"/>
                <inertia ixx="0.0" ixy="0.0" ixz="0.0" iyy="0.0" iyz="0.0" izz="0.0"/>
            </inertial>
            <visual name="">
                <origin xyz="0.0 0.0 0.0" rpy="0.0 0.0 0.0"/>
                <geometry>
                    <xacro:grabber2/>
                </geometry>
                <material name="">
                    <color rgba="1.0 0.0 0.0 1.0"/>
                    <texture filename=""/>
                </material>
            </visual>
            <collision>
                <origin xyz="0.0 0.0 0.0" rpy="0.0 0.0 0.0"/>
                <geometry>
                    <xacro:grabber2/>
                </geometry>
            </collision>
        </link>

        <joint name="joint0" type="fixed">
            <xacro:if value='${model == "original"}'>
                <origin xyz="0.55 -0.1 0.27" rpy="0.0 0.0 0.0"/>
            </xacro:if>
            <xacro:if value='${model == "prototype"}'>
                <origin xyz="0.0 0.0 0.27" rpy="0.0 0.0 0.0"/>
            </xacro:if>
            <parent link="base_link"/>
            <child link="link1"/>
            <axis xyz="0.0 0.0 0.0"/>
        </joint>

        <joint name="joint1" type="revolute">
            <origin xyz="0.0 -0.12 0.09" rpy="0.0 0.0 0.0"/>
            <parent link="link1"/>
            <child link="link2"/>
            <axis xyz="0.0 0.0 1"/>
            <dynamics damping="10.0" friction="10.0"/>
            <limit lower="-10.0" upper="10.0" effort="100" velocity="1.0"/>
        </joint>

        <joint name="joint2" type="revolute">
            <origin xyz="0.0 0.037 0.13" rpy="0.0 0.0 0.0"/>
            <parent link="link2"/>
            <child link="link3"/>
            <axis xyz="0.0 1 0.0"/>
            <dynamics damping="10.0" friction="10.0"/>
            <limit lower="-10.0" upper="10.0" effort="100" velocity="1.0"/>
        </joint>

        <joint name="joint3" type="revolute">
            <origin xyz="0.44 -0.037 0.0" rpy="0.0 0.0 0.0"/>
            <parent link="link3"/>
            <child link="link4"/>
            <axis xyz="0.0 1 0.0"/>
            <dynamics damping="10.0" friction="10.0"/>
            <limit lower="-10.0" upper="10.0" effort="100" velocity="1.0"/>
        </joint>

        <joint name="joint4" type="revolute">
            <origin xyz="0.42 0.0 0.0" rpy="0.0 0.0 0.0"/>
            <parent link="link4"/>
            <child link="link5"/>
            <axis xyz="0.0 1 0.0"/>
            <dynamics damping="10.0" friction="10.0"/>
            <limit lower="-10.0" upper="10.0" effort="100" velocity="1.0"/>
        </joint>

        <joint name="joint5" type="revolute">
            <origin xyz="0.0 0.12 0.0" rpy="0.0 0.0 0.0"/>
            <parent link="link5"/>
            <child link="link6"/>
            <axis xyz="0.0 0.0 1"/>
            <dynamics damping="10.0" friction="10.0"/>
            <limit lower="-10.0" upper="10.0" effort="100" velocity="1.0"/>
        </joint>

        <joint name="grabber_joint1" type="prismatic">
            <origin xyz="0.1 -0.31 -0.24" rpy="0.0 0.0 0.0"/>
            <parent link="link6"/>
            <child link="grabber1"/>
            <axis xyz="1 1 0.0"/>
            <limit lower="-0.02" upper="0.0224" effort="10" velocity="0.005"/>
        </joint>

        <joint name="grabber_joint2" type="prismatic">
            <origin xyz="0.1 0.31 -0.24" rpy="0.0 0.0 0.0"/>
            <parent link="link6"/>
            <child link="grabber2"/>
            <axis xyz="1 -1 0.0"/>
            <limit lower="-0.02" upper="0.0224" effort="10" velocity="0.005"/>
        </joint>

    </xacro:macro>
</robot>