<?xml version="1.0"?>

<robot xmlns:xacro="http://www.ros.org/wiki/xacro" name="ezrassor">
    
    <xacro:macro name="wheel" params="side pos">
        <link name="${side}_wheel_${pos}">
            <inertial>
                <!--
                    <origin xyz="0.0 0.0 0.0" rpy="1.5707 0.0 0.0"/>
                -->
                <xacro:if value='${side == "left"}'>
                    <origin xyz="0.0 0.0 0.0" rpy="0.0 0.0 0.0"/>
                </xacro:if>
                <xacro:unless value='${side == "left"}'>
                    <origin xyz="0 0 0" rpy="0 0 3.14159"/>
                </xacro:unless>
                <mass value="0.5"/>
                <xacro:cylinder_inertia m="0.5" r="0.18" h="0.2"/>
            </inertial>
            <visual name="${side}_wheel_${pos}_visual">
                <!--
                    <origin xyz="0.0 0.0 0.0" rpy="1.5707 0.0 0.0"/>
                -->
                <xacro:if value='${side == "left"}'>
                    <origin xyz="0.0 0.0 0.0" rpy="0.0 0.0 0.0"/>
                </xacro:if>
                <xacro:unless value='${side == "left"}'>
                    <origin xyz="0 0 0" rpy="0 0 3.14159"/>
                </xacro:unless>
                <geometry>
                    <!--
                        <cylinder radius="0.18" length="0.2"/>
                    -->
                    <xacro:robot_wheel/>
                </geometry>
                <!--
                    <material name="">
                        <color rgba="1.0 0.0 0.0 1.0"/>
                    </material>
                -->
            </visual>
            <collision>
                <!--
                    <origin xyz="0.0 0.0 0.0" rpy="1.5707 0.0 0.0"/>
                -->
                <xacro:if value='${side == "left"}'>
                    <origin xyz="0.0 0.0 0.0" rpy="0.0 0.0 0.0"/>
                </xacro:if>
                <xacro:unless value='${side == "left"}'>
                    <origin xyz="0 0 0" rpy="0 0 3.14159"/>
                </xacro:unless>
                <geometry>
                    <!--
                        <cylinder radius="0.18" length="0.2"/>
                    -->
                    <xacro:robot_wheel/>
                </geometry>
            </collision>
        </link>

        <joint name="${side}_wheel_${pos}_joint" type="continuous">
            <xacro:if value='${side == "right"}'>
                <xacro:if value='${pos == "front"}'>
                    <origin xyz="0.20 -0.285 0.0" rpy="0.0 0.0 0.0"/>
                </xacro:if>
                <xacro:unless value='${pos == "front"}'>
                    <origin xyz="-0.20 -0.285 0.0" rpy="0.0 0.0 0.0"/>
                </xacro:unless>
            </xacro:if>
            <xacro:unless value='${side == "right"}'>
                <xacro:if value='${pos == "front"}'>
                    <origin xyz="0.20 0.285 0.0" rpy="0.0 0.0 0.0"/>
                </xacro:if>
                <xacro:unless value='${pos == "front"}'>
                    <origin xyz="-0.20 0.285 0.0" rpy="0.0 0.0 0.0"/>
                </xacro:unless>
            </xacro:unless>
            <parent link="body"/>
            <child link="${side}_wheel_${pos}"/>
            <axis xyz="0.0 1 0.0"/>
        </joint>
    </xacro:macro>

</robot>